[2025-05-15 19:14:52] [error] Bot error: Unexpected SOCKS version number: 0
[2025-05-15 19:14:52] [error] Traceback (most recent call last):
  File "C:\Users\semtrip.DESKTOP-QDM923H\AppData\Roaming\Python\Python313\site-packages\python_socks\async_\asyncio\v2\_proxy.py", line 130, in _connect
    await connector.connect(
    ...<3 lines>...
    )
  File "C:\Users\semtrip.DESKTOP-QDM923H\AppData\Roaming\Python\Python313\site-packages\python_socks\_connectors\socks5_async.py", line 44, in connect
    reply: socks5.AuthMethodReply = conn.receive(data)
                                    ~~~~~~~~~~~~^^^^^^
  File "C:\Users\semtrip.DESKTOP-QDM923H\AppData\Roaming\Python\Python313\site-packages\python_socks\_protocols\socks5.py", line 333, in receive
    reply = AuthMethodReply.loads(data)
  File "C:\Users\semtrip.DESKTOP-QDM923H\AppData\Roaming\Python\Python313\site-packages\python_socks\_protocols\socks5.py", line 104, in loads
    raise ReplyError(f'Unexpected SOCKS version number: {ver}')
python_socks._protocols.errors.ReplyError: Unexpected SOCKS version number: 0

During handling of the above exception, another exception occurred:

Traceback (most recent call last):
  File "C:\Users\semtrip.DESKTOP-QDM923H\Documents\GitHub\stream_shop_service\backend\Service\Twitch\bot.py", line 53, in start
    async with self.session.head(url, timeout=10):
               ~~~~~~~~~~~~~~~~~^^^^^^^^^^^^^^^^^
  File "C:\Users\semtrip.DESKTOP-QDM923H\AppData\Roaming\Python\Python313\site-packages\aiohttp\client.py", line 1425, in __aenter__
    self._resp: _RetType = await self._coro
                           ^^^^^^^^^^^^^^^^
  File "C:\Users\semtrip.DESKTOP-QDM923H\AppData\Roaming\Python\Python313\site-packages\aiohttp\client.py", line 703, in _request
    conn = await self._connector.connect(
           ^^^^^^^^^^^^^^^^^^^^^^^^^^^^^^
        req, traces=traces, timeout=real_timeout
        ^^^^^^^^^^^^^^^^^^^^^^^^^^^^^^^^^^^^^^^^
    )
    ^
  File "C:\Users\semtrip.DESKTOP-QDM923H\AppData\Roaming\Python\Python313\site-packages\aiohttp\connector.py", line 548, in connect
    proto = await self._create_connection(req, traces, timeout)
            ^^^^^^^^^^^^^^^^^^^^^^^^^^^^^^^^^^^^^^^^^^^^^^^^^^^
  File "C:\Users\semtrip.DESKTOP-QDM923H\AppData\Roaming\Python\Python313\site-packages\aiohttp\connector.py", line 1056, in _create_connection
    _, proto = await self._create_direct_connection(req, traces, timeout)
               ^^^^^^^^^^^^^^^^^^^^^^^^^^^^^^^^^^^^^^^^^^^^^^^^^^^^^^^^^^
  File "C:\Users\semtrip.DESKTOP-QDM923H\AppData\Roaming\Python\Python313\site-packages\aiohttp\connector.py", line 1375, in _create_direct_connection
    transp, proto = await self._wrap_create_connection(
                    ^^^^^^^^^^^^^^^^^^^^^^^^^^^^^^^^^^^
    ...<7 lines>...
    )
    ^
  File "C:\Users\semtrip.DESKTOP-QDM923H\AppData\Roaming\Python\Python313\site-packages\aiohttp_socks\connector.py", line 66, in _wrap_create_connection
    return await self._connect_via_proxy(
           ^^^^^^^^^^^^^^^^^^^^^^^^^^^^^^
    ...<4 lines>...
    )
    ^
  File "C:\Users\semtrip.DESKTOP-QDM923H\AppData\Roaming\Python\Python313\site-packages\aiohttp_socks\connector.py", line 123, in _connect_via_proxy
    stream = await proxy.connect(
             ^^^^^^^^^^^^^^^^^^^^
    ...<4 lines>...
    )
    ^
  File "C:\Users\semtrip.DESKTOP-QDM923H\AppData\Roaming\Python\Python313\site-packages\python_socks\async_\asyncio\v2\_proxy.py", line 79, in connect
    return await self._connect(
           ^^^^^^^^^^^^^^^^^^^^
    ...<4 lines>...
    )
    ^
  File "C:\Users\semtrip.DESKTOP-QDM923H\AppData\Roaming\Python\Python313\site-packages\python_socks\async_\asyncio\v2\_proxy.py", line 143, in _connect
    raise ProxyError(e, error_code=e.error_code)
python_socks._errors.ProxyError: Unexpected SOCKS version number: 0

[2025-05-15 19:14:52] [error] Bot error: Unexpected SOCKS version number: 0
[2025-05-15 19:14:52] [error] Traceback (most recent call last):
  File "C:\Users\semtrip.DESKTOP-QDM923H\AppData\Roaming\Python\Python313\site-packages\python_socks\async_\asyncio\v2\_proxy.py", line 130, in _connect
    await connector.connect(
    ...<3 lines>...
    )
  File "C:\Users\semtrip.DESKTOP-QDM923H\AppData\Roaming\Python\Python313\site-packages\python_socks\_connectors\socks5_async.py", line 44, in connect
    reply: socks5.AuthMethodReply = conn.receive(data)
                                    ~~~~~~~~~~~~^^^^^^
  File "C:\Users\semtrip.DESKTOP-QDM923H\AppData\Roaming\Python\Python313\site-packages\python_socks\_protocols\socks5.py", line 333, in receive
    reply = AuthMethodReply.loads(data)
  File "C:\Users\semtrip.DESKTOP-QDM923H\AppData\Roaming\Python\Python313\site-packages\python_socks\_protocols\socks5.py", line 104, in loads
    raise ReplyError(f'Unexpected SOCKS version number: {ver}')
python_socks._protocols.errors.ReplyError: Unexpected SOCKS version number: 0

During handling of the above exception, another exception occurred:

Traceback (most recent call last):
  File "C:\Users\semtrip.DESKTOP-QDM923H\Documents\GitHub\stream_shop_service\backend\Service\Twitch\bot.py", line 53, in start
    async with self.session.head(url, timeout=10):
               ~~~~~~~~~~~~~~~~~^^^^^^^^^^^^^^^^^
  File "C:\Users\semtrip.DESKTOP-QDM923H\AppData\Roaming\Python\Python313\site-packages\aiohttp\client.py", line 1425, in __aenter__
    self._resp: _RetType = await self._coro
                           ^^^^^^^^^^^^^^^^
  File "C:\Users\semtrip.DESKTOP-QDM923H\AppData\Roaming\Python\Python313\site-packages\aiohttp\client.py", line 703, in _request
    conn = await self._connector.connect(
           ^^^^^^^^^^^^^^^^^^^^^^^^^^^^^^
        req, traces=traces, timeout=real_timeout
        ^^^^^^^^^^^^^^^^^^^^^^^^^^^^^^^^^^^^^^^^
    )
    ^
  File "C:\Users\semtrip.DESKTOP-QDM923H\AppData\Roaming\Python\Python313\site-packages\aiohttp\connector.py", line 548, in connect
    proto = await self._create_connection(req, traces, timeout)
            ^^^^^^^^^^^^^^^^^^^^^^^^^^^^^^^^^^^^^^^^^^^^^^^^^^^
  File "C:\Users\semtrip.DESKTOP-QDM923H\AppData\Roaming\Python\Python313\site-packages\aiohttp\connector.py", line 1056, in _create_connection
    _, proto = await self._create_direct_connection(req, traces, timeout)
               ^^^^^^^^^^^^^^^^^^^^^^^^^^^^^^^^^^^^^^^^^^^^^^^^^^^^^^^^^^
  File "C:\Users\semtrip.DESKTOP-QDM923H\AppData\Roaming\Python\Python313\site-packages\aiohttp\connector.py", line 1375, in _create_direct_connection
    transp, proto = await self._wrap_create_connection(
                    ^^^^^^^^^^^^^^^^^^^^^^^^^^^^^^^^^^^
    ...<7 lines>...
    )
    ^
  File "C:\Users\semtrip.DESKTOP-QDM923H\AppData\Roaming\Python\Python313\site-packages\aiohttp_socks\connector.py", line 66, in _wrap_create_connection
    return await self._connect_via_proxy(
           ^^^^^^^^^^^^^^^^^^^^^^^^^^^^^^
    ...<4 lines>...
    )
    ^
  File "C:\Users\semtrip.DESKTOP-QDM923H\AppData\Roaming\Python\Python313\site-packages\aiohttp_socks\connector.py", line 123, in _connect_via_proxy
    stream = await proxy.connect(
             ^^^^^^^^^^^^^^^^^^^^
    ...<4 lines>...
    )
    ^
  File "C:\Users\semtrip.DESKTOP-QDM923H\AppData\Roaming\Python\Python313\site-packages\python_socks\async_\asyncio\v2\_proxy.py", line 79, in connect
    return await self._connect(
           ^^^^^^^^^^^^^^^^^^^^
    ...<4 lines>...
    )
    ^
  File "C:\Users\semtrip.DESKTOP-QDM923H\AppData\Roaming\Python\Python313\site-packages\python_socks\async_\asyncio\v2\_proxy.py", line 143, in _connect
    raise ProxyError(e, error_code=e.error_code)
python_socks._errors.ProxyError: Unexpected SOCKS version number: 0

